<?xml version="1.0"?>

<!-- units are in SI -->
<robot name="harpy">

    <!-- *************************** MATERIALS *************************** -->
    <material name="black">
        <color rgba="0.2 0.2 0.2 1"/>
    </material>
    <material name="black_seethrough">
        <color rgba="0.2 0.2 0.2 0.1"/>
    </material>

    <!-- *************************** LINKS *************************** -->
    <!-- Torso -->
    <link name="Torso">
        <inertial>
            <origin rpy="0 0 0" xyz="0 0 0.15"/>
            <mass value="2.3"/>
            <inertia ixx="0.026588" ixy="0" ixz="0" iyy="0.026588" iyz="0" izz="0.026588"/>   
        </inertial>
        <visual>
            <geometry>
                <mesh filename="../meshes/TorsoPelvis.OBJ"/>
            </geometry>
            <material name="black"/>
        </visual>
        <collision>
            <origin rpy="0 0 0" xyz="0 0 0.15"/>
            <geometry>
                <sphere radius="0.17"/>
            </geometry>
        </collision>
    </link>

    <!-- Thrusters -->
    <link name="ThrusterRight">
        <inertial>
            <origin rpy="0 0 0" xyz="-1.0844e-09 -0.049128 -0.0051344"/>
            <mass value="0.9"/>
            <inertia ixx="0.00080744" ixy="3.9847e-11" ixz="-1.1643e-10" iyy="0.00077366" iyz="-4.029e-06" izz="0.00071101"/>   
        </inertial>
        <visual>
            <geometry>
                <mesh filename="../meshes/Thruster.OBJ"/>
            </geometry>
            <material name="black"/>
        </visual>
    </link>
    <link name="ThrusterLeft">
        <inertial>
            <origin rpy="0 0 0" xyz="-1.0844e-09 -0.049128 -0.0051344"/>
            <mass value="0.9"/>
            <inertia ixx="0.00080744" ixy="3.9847e-11" ixz="-1.1643e-10" iyy="0.00077366" iyz="-4.029e-06" izz="0.00071101"/>   
        </inertial>
        <visual>
            <geometry>
                <mesh filename="../meshes/Thruster.OBJ"/>
            </geometry>
            <material name="black"/>
        </visual>
    </link>

    <!-- Hips -->
    <link name="HipRight">
        <inertial>
            <origin rpy="0 0 0" xyz="0.04036 0.032494 8.7274e-09"/>
            <mass value="1"/>
            <inertia ixx="0.00097125" ixy="-0.00043562" ixz="-1.1631e-09" iyy="0.0010713" iyz="-7.0712e-10" izz="0.0015463"/>   
        </inertial>
        <visual>
            <geometry>
                <mesh filename="../meshes/Hip.OBJ"/>
            </geometry>
            <material name="black"/>
        </visual>
    </link>
    <link name="HipLeft">
        <inertial>
            <origin rpy="0 0 0" xyz="0.04036 0.032494 8.7274e-09"/>
            <mass value="1"/>
            <inertia ixx="0.00097125" ixy="-0.00043562" ixz="-1.1631e-09" iyy="0.0010713" iyz="-7.0712e-10" izz="0.0015463"/>   
        </inertial>
        <visual>
            <geometry>
                <mesh filename="../meshes/Hip.OBJ"/>
            </geometry>
            <material name="black"/>
        </visual>
    </link>

    <!-- Simplified upper leg links -->
    <link name="FemurRight">
        <inertial>
            <origin rpy="0 0 0" xyz="0 0 -0.15"/>
            <mass value="0.1"/>
            <inertia ixx="0.00086013" ixy="0" ixz="0" iyy="0.00086013" iyz="0" izz="1.1109e-05"/>   
        </inertial>
        <visual>
            <origin rpy="0 0 0" xyz="0.0 0.0 -0.15"/>
            <geometry>
                <capsule length="0.3" radius="0.015"/>
            </geometry>
            <material name="black_seethrough"/>
        </visual>
    </link>
    <link name="FemurLeft">
        <inertial>
            <origin rpy="0 0 0" xyz="0 0 -0.15"/>
            <mass value="0.1"/>
            <inertia ixx="0.00086013" ixy="0" ixz="0" iyy="0.00086013" iyz="0" izz="1.1109e-05"/>   
        </inertial>
        <visual>
            <origin rpy="0 0 0" xyz="0.0 0.0 -0.15"/>
            <geometry>
                <capsule length="0.3" radius="0.015"/>
            </geometry>
            <material name="black_seethrough"/>
        </visual>
    </link>

    <!-- Simplified lower leg links -->
    <link name="TibiaRight">
        <inertial>
            <origin rpy="0 0 0" xyz="0 0 -0.15"/>
            <mass value="0.1"/>
            <inertia ixx="0.00086013" ixy="0" ixz="0" iyy="0.00086013" iyz="0" izz="1.1109e-05"/>   
        </inertial>
        <visual>
            <origin rpy="0 0 0" xyz="0.0 0.0 -0.15"/>
            <geometry>
                <capsule length="0.3" radius="0.015"/>
            </geometry>
            <material name="black_seethrough"/>
        </visual>
    </link>
    <link name="TibiaLeft">
        <inertial>
            <origin rpy="0 0 0" xyz="0 0 -0.15"/>
            <mass value="0.1"/>
            <inertia ixx="0.00086013" ixy="0" ixz="0" iyy="0.00086013" iyz="0" izz="1.1109e-05"/>   
        </inertial>
        <visual>
            <origin rpy="0 0 0" xyz="0.0 0.0 -0.15"/>
            <geometry>
                <capsule length="0.3" radius="0.015"/>
            </geometry>
            <material name="black_seethrough"/>
        </visual>
    </link>

    <!-- Feet -->
    <link name="FootRight">
        <inertial>
            <origin rpy="0 0 0" xyz="0 0 0"/>
            <mass value="0.001"/>
            <inertia ixx="1.024e-07" ixy="0" ixz="0" iyy="1.024e-07" iyz="0" izz="1.024e-07"/>
        </inertial>
        <visual>
            <origin rpy="0 0 0" xyz="0.0 0.0 0.0"/>
            <geometry>
                <sphere radius="0.016"/>
            </geometry>
            <material name="black"/>
        </visual>
        <collision>
            <origin rpy="0 0 0" xyz="0.0 0.0 0.0"/>
            <geometry>
                <sphere radius="0.016"/>
            </geometry>
        </collision>
    </link>
    <link name="FootLeft">
        <inertial>
            <origin rpy="0 0 0" xyz="0 0 0"/>
            <mass value="0.001"/>
            <inertia ixx="1.024e-07" ixy="0" ixz="0" iyy="1.024e-07" iyz="0" izz="1.024e-07"/>
        </inertial>
        <visual>
            <origin rpy="0 0 0" xyz="0.0 0.0 0.0"/>
            <geometry>
                <sphere radius="0.016"/>
            </geometry>
            <material name="black"/>
        </visual>
        <collision>
            <origin rpy="0 0 0" xyz="0.0 0.0 0.0"/>
            <geometry>
                <sphere radius="0.016"/>
            </geometry>
        </collision>
    </link>

    <!-- Ground -->
    <link name="ground">
        <inertial>  <!-- dummy inertia: ground is welded to the world frame -->
            <mass value="1"/>
            <inertia ixx="0.0001" ixy="0" ixz="0" iyy="0.0001" iyz="0" izz="0.0001"/>
        </inertial>
        <collision>
            <origin rpy="0 0 0" xyz="0 0 -50"/>
            <geometry>
                <box size="100 100 100"/>
            </geometry>
        </collision>
    </link>


    <!-- *************************** JOINTS *************************** -->
    <!-- Torso to world -->
    <joint name="World_Torso" type="planar">
        <parent link="world"/>
        <child link="Torso"/>
        <axis xyz="0 -1 0"/>
        <origin xyz="0 0 0" rpy="0 0 0"/>
    </joint>

    <!-- Thrusters to Torso -->
    <joint name="Torso_ThrusterRight" type="fixed">
        <parent link="Torso"/>
        <child link="ThrusterRight"/>
        <axis xyz="0 1 0"/>
        <origin xyz="-0.028 -0.2 0.16" rpy="0.0 0.0 0.0"/>
    </joint>
    <joint name="Torso_ThrusterLeft" type="fixed">
        <parent link="Torso"/>
        <child link="ThrusterLeft"/>
        <axis xyz="0 1 0"/>
        <origin xyz="-0.028 0.2 0.16" rpy="0.0 0.0 3.1416"/>
    </joint>
    
    <!-- Hips to Torso -->
    <joint name="Torso_HipRight" type="fixed">
        <parent link="Torso"/>
        <child link="HipRight"/>
        <axis xyz="1 0 0"/>
        <origin xyz="0.0 -0.1 0.0" rpy="0.0 0.0 0.0"/>
    </joint>
    <joint name="Torso_HipLeft" type="fixed">
        <parent link="Torso"/>
        <child link="HipLeft"/>
        <axis xyz="1 0 0"/>
        <origin xyz="0.0 0.1 0.0" rpy="3.1416 0.0 0.0"/>
    </joint>

    <!-- Femur to Hips -->
    <!-- nominal angle: -0.45 rad-->
    <joint name="HipRight_FemurRight" type="continuous">
        <parent link="HipRight"/>
        <child link="FemurRight"/>
        <axis xyz="0 1 0"/>
        <origin xyz="0.06549 0.0 0.0" rpy="0.0 0.0 0.0"/>
    </joint>
    <joint name="HipLeft_FemurLeft" type="continuous">
        <parent link="HipLeft"/>
        <child link="FemurLeft"/>
        <axis xyz="0 1 0"/>
        <origin xyz="0.06549 0.0 0.0" rpy="-3.14159 0.0 0.0"/>
    </joint>

    <!-- Tibia to Femur -->
    <!-- nominal angle: 1.15 rad-->
    <joint name="FemurRight_TibiaRight" type="continuous">
        <parent link="FemurRight"/>
        <child link="TibiaRight"/>
        <axis xyz="0 1 0"/>
        <origin xyz="0.0 0.035 -0.3" rpy="0.0 0.0 0.0"/>
    </joint>
    <joint name="FemurLeft_TibiaLeft" type="continuous">
        <parent link="FemurLeft"/>
        <child link="TibiaLeft"/>
        <axis xyz="0 1 0"/>
        <origin xyz="0.0 -0.035 -0.3" rpy="0.0 0.0 0.0"/>
    </joint>

    <!-- Feet to Tibia -->
    <joint name="TibiaRight_FootRight" type="fixed">
        <parent link="TibiaRight"/>
        <child link="FootRight"/>
        <axis xyz="0 1 0"/>
        <origin xyz="0.0 0.0 -0.3" rpy="0.0 0.0 0.0"/>
    </joint>
    <joint name="TibiaLeft_FootLeft" type="fixed">
        <parent link="TibiaLeft"/>
        <child link="FootLeft"/>
        <axis xyz="0 1 0"/>
        <origin xyz="0.0 0.0 -0.3" rpy="0.0 0.0 0.0"/>
    </joint>

    <!-- World to ground -->
    <joint name="world_ground" type="fixed">
        <parent link="world"/>
        <child link="ground"/>
        <origin xyz="0 0 0" rpy="0 0 0"/>
    </joint>

    <!-- *************************** ACTUATORS *************************** -->
    <transmission name="HipRight_FemurRight">
        <type>transmission_interface/SimpleTransmission</type>
        <joint name="HipRight_FemurRight"/>
        <actuator name="HipRight_FemurRight"/>
    </transmission>
    <transmission name="HipLeft_FemurLeft">
        <type>transmission_interface/SimpleTransmission</type>
        <joint name="HipLeft_FemurLeft"/>
        <actuator name="HipLeft_FemurLeft"/>
    </transmission>
    
    <transmission name="FemurRight_TibiaRight">
        <type>transmission_interface/SimpleTransmission</type>
        <joint name="FemurRight_TibiaRight"/>
        <actuator name="FemurRight_TibiaRight"/>
    </transmission>
    <transmission name="FemurLeft_TibiaLeft">
        <type>transmission_interface/SimpleTransmission</type>
        <joint name="FemurLeft_TibiaLeft"/>
        <actuator name="FemurLeft_TibiaLeft"/>
    </transmission>
    
</robot>
